experimentalAnalysis/hash_rb_Experimental/test-f1-5.txt
500000
buy 84
buy 63
buy 98
buy 73
buy 58
buy 98
buy 96
buy 60
buy 63
buy 91
buy 86
buy 77
buy 84
buy 86
buy 88
buy 54
buy 69
buy 67
buy 86
buy 55
buy 60
buy 79
buy 54
buy 83
buy 53
buy 54
buy 57
buy 86
buy 60
buy 89
buy 52
buy 60
buy 70
buy 77
buy 98
buy 73
buy 81
buy 66
buy 92
buy 98
buy 98
buy 99
buy 98
buy 71
buy 92
buy 82
buy 56
buy 67
buy 92
buy 99
buy 71
buy 56
buy 85
buy 99
buy 90
buy 54
buy 85
buy 81
buy 88
buy 52
buy 95
buy 66
buy 54
buy 62
buy 75
buy 91
buy 92
buy 82
buy 77
buy 75
buy 77
buy 70
buy 68
buy 54
buy 72
buy 63
buy 70
buy 84
buy 98
buy 95
buy 78
buy 94
buy 70
buy 79
buy 89
buy 97
buy 67
buy 51
buy 83
buy 92
buy 60
buy 90
buy 100
buy 54
buy 72
buy 98
buy 81
buy 74
buy 50
buy 52
buy 90
buy 80
buy 83
buy 61
buy 62
buy 83
buy 92
buy 91
buy 72
buy 97
buy 82
buy 82
buy 50
buy 77
buy 55
buy 86
buy 50
buy 62
buy 53
buy 76
buy 99
buy 91
buy 82
buy 91
buy 74
buy 59
buy 71
buy 90
buy 79
buy 96
buy 55
buy 92
buy 77
buy 59
buy 66
buy 61
buy 96
buy 51
buy 62
buy 66
buy 97
buy 97
buy 53
buy 80
buy 53
buy 76
buy 56
buy 67
buy 70
buy 79
buy 67
buy 93
buy 67
buy 98
buy 76
buy 72
buy 73
buy 79
buy 95
buy 86
buy 62
buy 95
buy 99
buy 83
buy 75
buy 77
buy 92
buy 67
buy 88
buy 68
buy 62
buy 70
buy 59
buy 65
buy 100
buy 91
buy 89
buy 80
buy 51
buy 56
buy 86
buy 87
buy 99
buy 60
buy 70
buy 58
buy 58
buy 51
buy 68
buy 96
buy 85
buy 90
buy 74
buy 66
buy 90
buy 98
buy 64
buy 70
buy 96
buy 52
buy 56
buy 71
buy 68
buy 78
buy 98
buy 72
buy 84
buy 87
buy 73
buy 81
buy 61
buy 79
buy 68
buy 91
buy 77
buy 81
buy 61
buy 61
buy 66
buy 66
buy 85
buy 60
buy 64
buy 55
buy 71
buy 67
buy 79
buy 51
buy 65
buy 72
buy 58
buy 91
buy 66
buy 98
buy 52
buy 64
buy 54
buy 98
buy 63
buy 65
buy 95
buy 91
buy 72
buy 80
buy 71
buy 100
buy 100
buy 69
buy 83
buy 80
buy 65
buy 53
buy 86
buy 95
buy 83
buy 61
buy 65
buy 76
buy 65
buy 59
buy 76
buy 87
buy 52
buy 67
buy 86
buy 97
buy 64
buy 57
buy 100
buy 80
buy 94
buy 66
buy 85
buy 85
buy 82
buy 64
buy 60
buy 65
buy 99
buy 80
buy 50
buy 79
buy 79
buy 60
buy 52
buy 87
buy 54
buy 53
buy 59
buy 73
buy 94
buy 70
buy 68
buy 70
buy 75
buy 66
buy 97
buy 59
buy 52
buy 83
buy 76
buy 66
buy 72
buy 58
buy 76
buy 50
buy 84
buy 72
buy 81
buy 70
buy 68
buy 57
buy 61
buy 84
buy 75
buy 95
buy 92
buy 50
buy 97
buy 86
buy 52
buy 85
buy 84
buy 60
buy 53
buy 70
buy 64
buy 61
buy 76
buy 72
buy 52
buy 80
buy 78
buy 51
buy 71
buy 72
buy 70
buy 85
buy 56
buy 77
buy 93
buy 58
buy 64
buy 90
buy 71
buy 51
buy 58
buy 63
buy 76
buy 52
buy 63
buy 54
buy 51
buy 66
buy 67
buy 69
buy 68
buy 87
buy 67
buy 93
buy 94
buy 87
buy 69
buy 70
buy 81
buy 64
buy 63
buy 53
buy 97
buy 50
buy 59
buy 86
buy 73
buy 60
buy 66
buy 65
buy 75
buy 93
buy 88
buy 72
buy 90
buy 73
buy 62
buy 93
buy 98
buy 73
buy 78
buy 84
buy 55
buy 59
buy 93
buy 63
buy 51
buy 53
buy 68
buy 88
buy 95
buy 100
buy 65
buy 70
buy 50
buy 63
buy 64
buy 89
buy 72
buy 74
buy 92
buy 70
buy 84
buy 62
buy 94
buy 89
buy 62
buy 69
buy 78
buy 50
buy 75
buy 99
buy 72
buy 59
buy 65
buy 100
buy 68
buy 54
buy 94
buy 58
buy 79
buy 91
buy 72
buy 95
buy 56
buy 83
buy 61
buy 99
buy 79
buy 51
buy 78
buy 82
buy 64
buy 90
buy 56
buy 80
buy 71
buy 94
buy 66
buy 88
buy 71
buy 62
buy 50
buy 98
buy 94
buy 59
buy 69
buy 77
buy 73
buy 89
buy 77
buy 85
buy 99
buy 99
buy 92
buy 79
buy 75
buy 89
buy 59
buy 82
buy 94
buy 73
buy 68
buy 82
buy 67
buy 78
buy 53
buy 72
buy 52
buy 100
buy 90
buy 57
buy 75
buy 65
buy 84
buy 52
buy 80
buy 96
buy 97
buy 81
buy 56
buy 74
buy 97
buy 51
buy 83
buy 61
buy 88
buy 70
buy 51
buy 94
buy 74
buy 93
buy 97
buy 64
buy 67
buy 95
buy 68
buy 54
buy 85
buy 61
buy 77
buy 55
buy 68
buy 74
buy 95
buy 80
buy 99
buy 74
buy 82
buy 71
buy 78
buy 67
buy 57
buy 85
buy 85
buy 65
buy 50
buy 52
buy 82
buy 60
buy 82
buy 54
buy 94
buy 53
buy 75
buy 81
buy 95
buy 65
buy 78
buy 53
buy 55
buy 58
buy 72
buy 58
buy 83
buy 95
buy 93
buy 96
buy 83
buy 57
buy 78
buy 81
buy 52
buy 84
buy 71
buy 94
buy 53
buy 72
buy 96
buy 64
buy 51
buy 96
buy 65
buy 84
buy 53
buy 58
buy 80
buy 69
buy 63
buy 85
buy 94
buy 58
buy 61
buy 67
buy 50
buy 82
buy 83
buy 67
buy 64
buy 57
buy 76
buy 55
buy 96
buy 61
buy 98
buy 69
buy 81
buy 55
buy 66
buy 82
buy 84
buy 53
buy 69
buy 97
buy 84
buy 100
buy 91
buy 89
buy 73
buy 92
buy 78
buy 85
buy 70
buy 61
buy 82
buy 96
buy 55
buy 60
buy 76
buy 73
buy 86
buy 68
buy 78
buy 96
buy 91
buy 100
buy 78
buy 70
buy 93
buy 89
buy 79
buy 79
buy 93
buy 72
buy 67
buy 90
buy 68
buy 95
buy 52
buy 88
buy 64
buy 61
buy 62
buy 57
buy 91
buy 55
buy 97
buy 64
buy 84
buy 55
buy 74
buy 73
buy 71
buy 67
buy 68
buy 60
buy 62
buy 83
buy 64
buy 86
buy 82
buy 85
buy 73
buy 99
buy 92
buy 89
buy 55
buy 71
buy 75
buy 85
buy 71
buy 57
buy 52
buy 65
buy 58
buy 84
buy 54
buy 72
buy 70
buy 71
buy 99
buy 84
buy 93
buy 86
buy 93
buy 66
buy 52
buy 77
buy 55
buy 99
buy 69
buy 97
buy 91
buy 83
buy 64
buy 51
buy 60
buy 100
buy 77
buy 60
buy 58
buy 51
buy 97
buy 96
buy 87
buy 70
buy 84
buy 65
buy 97
buy 72
buy 55
buy 88
buy 68
buy 80
buy 60
buy 83
buy 70
buy 58
buy 74
buy 91
buy 81
buy 74
buy 60
buy 99
buy 65
buy 97
buy 53
buy 91
buy 72
buy 78
buy 93
buy 97
buy 58
buy 84
buy 87
buy 84
buy 51
buy 100
buy 74
buy 89
buy 91
buy 50
buy 54
buy 68
buy 83
buy 92
buy 75
buy 85
buy 94
buy 98
buy 96
buy 76
buy 51
buy 79
buy 57
buy 54
buy 67
buy 88
buy 73
buy 92
buy 87
buy 81
buy 91
buy 98
buy 93
buy 87
buy 50
buy 82
buy 55
buy 81
buy 54
buy 61
buy 57
buy 63
buy 64
buy 61
buy 63
buy 55
buy 86
buy 88
buy 65
buy 56
buy 58
buy 55
buy 85
buy 94
buy 78
buy 85
buy 66
buy 88
buy 75
buy 65
buy 78
buy 97
buy 84
buy 71
buy 64
buy 84
buy 90
buy 97
buy 64
buy 62
buy 89
buy 82
buy 57
buy 70
buy 84
buy 56
buy 96
buy 99
buy 62
buy 86
buy 68
buy 83
buy 74
buy 61
buy 79
buy 85
buy 97
buy 79
buy 70
buy 77
buy 66
buy 93
buy 74
buy 96
buy 56
buy 69
buy 81
buy 71
buy 61
buy 97
buy 77
buy 71
buy 50
buy 84
buy 68
buy 56
buy 74
buy 68
buy 74
buy 71
buy 97
buy 93
buy 89
buy 64
buy 74
buy 75
buy 52
buy 96
buy 60
buy 59
buy 57
buy 93
buy 96
buy 88
buy 65
buy 76
buy 88
buy 82
buy 66
buy 89
buy 65
buy 91
buy 54
buy 66
buy 57
buy 100
buy 94
buy 63
buy 81
buy 86
buy 62
buy 95
buy 89
buy 82
buy 85
buy 100
buy 86
buy 54
buy 57
buy 52
buy 70
buy 66
buy 78
buy 63
buy 78
buy 92
buy 62
buy 53
buy 94
buy 96
buy 94
buy 84
buy 89
buy 82
buy 95
buy 79
buy 81
buy 72
buy 89
buy 51
buy 50
buy 66
buy 78
buy 51
buy 64
buy 83
buy 75
buy 74
buy 64
buy 59
buy 62
buy 63
buy 78
buy 76
buy 54
buy 52
buy 84
buy 84
buy 50
buy 50
buy 78
buy 63
buy 62
buy 86
buy 87
buy 75
buy 88
buy 64
buy 79
buy 65
buy 70
buy 74
buy 96
buy 70
buy 64
buy 62
buy 63
buy 65
buy 79
buy 92
buy 98
buy 100
buy 85
buy 54
buy 52
buy 57
buy 84
buy 62
buy 79
buy 82
buy 71
buy 51
buy 71
buy 53
buy 52
buy 78
buy 67
buy 67
buy 67
buy 88
buy 98
buy 67
buy 87
buy 85
buy 65
buy 93
buy 94
buy 80
buy 53
buy 83
buy 50
buy 91
buy 78
buy 53
buy 94
buy 100
buy 97
buy 81
buy 94
buy 56
buy 86
buy 64
buy 77
buy 50
buy 66
buy 64
buy 88
buy 59
buy 90
buy 95
buy 71
buy 69
buy 61
buy 60
buy 73
buy 64
buy 89
buy 56
buy 90
buy 93
buy 98
buy 50
buy 71
buy 97
buy 63
buy 62
buy 86
buy 67
buy 86
buy 97
buy 80
buy 51
buy 65
buy 77
buy 82
buy 84
buy 87
buy 52
buy 100
buy 76
buy 62
buy 92
buy 76
buy 61
buy 96
buy 68
buy 89
buy 61
buy 92
buy 59
buy 59
buy 52
buy 50
buy 69
buy 91
buy 72
buy 67
buy 58
buy 81
buy 99
buy 66
buy 57
buy 84
buy 72
buy 59
buy 97
buy 55
buy 65
buy 72
buy 100
buy 90
buy 93
buy 53
buy 88
buy 51
buy 78
buy 88
buy 65
buy 80
buy 68
buy 80
buy 100
buy 63
buy 67
buy 100
buy 65
buy 95
buy 80
buy 61
buy 69
buy 73
buy 68
buy 66
buy 57
buy 95
buy 79
buy 66
buy 71
buy 95
buy 57
buy 96
buy 55
buy 71
buy 92
buy 83
buy 91
buy 77
buy 65
buy 54
buy 72
buy 68
buy 62
buy 82
buy 100
buy 71
buy 98
buy 95
buy 90
buy 58
buy 96
buy 86
buy 99
buy 85
buy 55
buy 52
buy 76
buy 93
buy 69
buy 64
buy 55
buy 91
buy 68
buy 54
buy 69
buy 66
buy 91
buy 90
buy 77
buy 93
buy 77
buy 53
buy 51
buy 93
buy 84
buy 73
buy 86
buy 85
buy 85
buy 95
buy 60
buy 76
buy 77
buy 97
buy 76
buy 67
buy 96
buy 95
buy 99
buy 80
buy 56
buy 54
buy 54
buy 78
buy 64
buy 50
buy 87
buy 96
buy 70
buy 80
buy 93
buy 88
