main/test_files/test-f1-1.txt
10000
sell 83
buy 88
sell 125
buy 79
sell 120
buy 78
sell 88
buy 71
sell 129
buy 73
sell 115
buy 79
sell 101
buy 76
sell 81
buy 58
sell 110
buy 88
sell 116
buy 53
sell 121
buy 65
sell 85
buy 78
sell 95
buy 90
sell 97
buy 66
sell 105
buy 68
sell 97
buy 88
sell 91
buy 81
sell 104
buy 76
sell 114
buy 85
sell 113
buy 81
sell 83
buy 90
sell 114
buy 93
sell 88
buy 86
sell 103
buy 64
sell 106
buy 65
sell 113
buy 56
sell 101
buy 67
sell 84
buy 74
sell 105
buy 92
sell 102
buy 59
sell 103
buy 86
sell 126
buy 57
sell 129
buy 58
sell 120
buy 98
sell 99
buy 53
sell 124
buy 88
sell 80
buy 95
sell 101
buy 78
sell 112
buy 96
sell 97
buy 78
sell 83
buy 90
sell 96
buy 96
sell 84
buy 97
sell 81
buy 66
sell 115
buy 93
sell 123
buy 58
sell 116
buy 66
sell 86
buy 95
sell 108
buy 90
sell 102
buy 65
sell 120
buy 70
sell 130
buy 94
sell 100
buy 90
sell 124
buy 79
sell 97
buy 77
sell 101
buy 98
sell 89
buy 90
sell 90
buy 85
sell 82
buy 91
sell 90
buy 84
sell 96
buy 99
sell 129
buy 75
sell 116
buy 91
sell 83
buy 64
sell 87
buy 100
sell 80
buy 88
sell 107
buy 74
sell 124
buy 81
sell 105
buy 51
sell 130
buy 56
sell 81
buy 94
sell 101
buy 55
sell 92
buy 95
sell 120
buy 74
sell 108
buy 91
sell 98
buy 74
sell 129
buy 90
sell 113
buy 58
sell 120
buy 89
sell 83
buy 92
sell 103
buy 73
sell 95
buy 53
sell 115
buy 70
sell 90
buy 62
sell 104
buy 53
sell 88
buy 53
sell 119
buy 100
sell 80
buy 52
sell 118
buy 73
sell 80
buy 90
sell 128
buy 87
sell 107
buy 51
sell 102
buy 78
sell 94
buy 59
sell 117
buy 71
sell 84
buy 96
sell 113
buy 87
sell 110
buy 79
sell 129
buy 99
sell 102
buy 69
sell 130
buy 55
sell 92
buy 94
sell 91
buy 96
sell 127
buy 86
sell 118
buy 58
sell 81
buy 61
sell 124
buy 53
sell 115
buy 86
sell 114
buy 81
sell 90
buy 72
sell 88
buy 82
sell 105
buy 73
sell 84
buy 99
sell 89
buy 55
sell 80
buy 50
sell 127
buy 77
sell 101
buy 84
sell 98
buy 55
sell 129
buy 83
sell 114
buy 88
sell 113
buy 71
sell 121
buy 100
sell 127
buy 52
sell 130
buy 99
sell 130
buy 58
sell 107
buy 92
sell 98
buy 84
sell 80
buy 55
sell 130
buy 62
sell 124
buy 65
sell 81
buy 95
sell 118
buy 70
sell 102
buy 53
sell 84
buy 57
sell 121
buy 53
sell 85
buy 74
sell 114
buy 57
sell 102
buy 69
sell 86
buy 67
sell 100
buy 60
sell 113
buy 74
sell 80
buy 85
sell 84
buy 83
sell 92
buy 60
sell 113
buy 98
sell 126
buy 93
sell 90
buy 70
sell 93
buy 59
sell 99
buy 55
sell 114
buy 94
sell 111
buy 77
sell 114
buy 71
sell 86
buy 96
sell 85
buy 77
sell 102
buy 55
sell 96
buy 96
sell 130
buy 99
sell 108
buy 51
sell 112
buy 100
sell 92
buy 98
sell 117
buy 79
sell 85
buy 54
sell 98
buy 95
sell 100
buy 67
sell 94
buy 50
sell 99
buy 68
sell 118
buy 50
sell 83
buy 80
sell 107
buy 65
sell 104
buy 50
sell 127
buy 64
sell 97
buy 61
sell 113
buy 58
sell 99
buy 52
sell 116
buy 62
sell 107
buy 74
sell 119
buy 94
sell 111
buy 97
sell 127
buy 60
sell 110
buy 73
sell 80
buy 55
sell 92
buy 81
sell 96
buy 74
sell 96
buy 88
sell 110
buy 100
sell 130
buy 76
sell 116
buy 61
sell 124
buy 54
sell 122
buy 90
sell 86
buy 63
sell 96
buy 89
sell 95
buy 84
sell 110
buy 60
sell 87
buy 57
sell 94
buy 80
sell 99
buy 54
sell 114
buy 98
sell 125
buy 63
sell 128
buy 59
sell 89
buy 73
sell 103
buy 56
sell 108
buy 68
sell 126
buy 62
sell 93
buy 80
sell 96
buy 76
sell 81
buy 81
sell 104
buy 100
sell 105
buy 92
sell 90
buy 67
sell 83
buy 66
sell 106
buy 85
sell 110
buy 76
sell 103
buy 59
sell 128
buy 60
sell 122
buy 73
sell 87
buy 86
sell 128
buy 79
sell 109
buy 51
sell 127
buy 58
sell 120
buy 51
sell 127
buy 98
sell 98
buy 63
sell 87
buy 61
sell 91
buy 95
sell 117
buy 58
sell 80
buy 90
sell 120
buy 63
sell 91
buy 78
sell 114
buy 67
sell 82
buy 76
sell 108
buy 50
sell 119
buy 75
sell 123
buy 89
sell 105
buy 81
sell 83
buy 84
sell 112
buy 66
sell 95
buy 77
sell 127
buy 54
sell 115
buy 69
sell 103
buy 81
sell 111
buy 81
sell 106
buy 61
sell 124
buy 95
sell 105
buy 61
sell 107
buy 90
sell 102
buy 53
sell 112
buy 96
sell 88
buy 96
sell 103
buy 69
sell 113
buy 80
sell 117
buy 91
sell 107
buy 61
sell 85
buy 73
sell 123
buy 68
sell 85
buy 70
sell 96
buy 79
sell 88
buy 97
sell 110
buy 68
sell 86
buy 62
sell 95
buy 73
sell 98
buy 62
sell 127
buy 85
sell 116
buy 71
sell 114
buy 50
sell 89
buy 51
sell 121
buy 98
sell 83
buy 55
sell 85
buy 56
sell 102
buy 98
sell 98
buy 93
sell 102
buy 82
sell 86
buy 97
sell 97
buy 74
sell 85
buy 82
sell 123
buy 80
sell 99
buy 56
sell 108
buy 78
sell 122
buy 80
sell 101
buy 71
sell 117
buy 87
sell 129
buy 77
sell 90
buy 70
sell 105
buy 61
sell 107
buy 87
sell 104
buy 69
sell 108
buy 97
sell 92
buy 88
sell 122
buy 80
sell 128
buy 55
sell 92
buy 52
sell 94
buy 99
sell 95
buy 93
sell 87
buy 85
sell 106
buy 76
sell 129
buy 77
sell 91
buy 58
sell 118
buy 74
sell 122
buy 84
sell 128
buy 59
sell 113
buy 87
sell 89
buy 88
sell 89
buy 63
sell 82
buy 99
sell 122
buy 85
sell 86
buy 67
sell 82
buy 50
sell 85
buy 69
sell 118
buy 83
sell 89
buy 55
sell 106
buy 66
sell 98
buy 90
sell 120
buy 89
sell 83
buy 60
sell 112
buy 80
sell 96
buy 95
sell 119
buy 70
sell 95
buy 60
sell 113
buy 67
sell 129
buy 82
sell 116
buy 92
sell 128
buy 80
sell 116
buy 65
sell 112
buy 63
sell 80
buy 82
sell 81
buy 93
sell 83
buy 98
sell 90
buy 100
sell 123
buy 81
sell 119
buy 70
sell 120
buy 85
sell 127
buy 59
sell 129
buy 65
sell 90
buy 83
sell 112
buy 57
sell 120
buy 63
sell 99
buy 68
sell 122
buy 82
sell 119
buy 68
sell 111
buy 79
sell 99
buy 67
sell 119
buy 55
sell 119
buy 99
sell 118
buy 93
sell 89
buy 96
sell 87
buy 87
sell 115
buy 66
sell 123
buy 86
sell 110
buy 85
sell 93
buy 92
sell 96
buy 67
sell 86
buy 67
sell 85
buy 81
sell 129
buy 95
sell 82
buy 53
sell 130
buy 77
sell 94
buy 50
sell 106
buy 72
sell 125
buy 51
sell 84
buy 88
sell 102
buy 88
sell 129
buy 54
sell 114
buy 83
sell 108
buy 71
sell 125
buy 87
sell 101
buy 87
sell 113
buy 68
sell 86
buy 73
sell 121
buy 76
sell 106
buy 93
sell 108
buy 66
sell 87
buy 100
sell 122
buy 66
sell 97
buy 100
sell 124
buy 53
sell 128
buy 98
sell 91
buy 56
sell 121
buy 84
sell 85
buy 63
sell 84
buy 62
sell 116
buy 65
sell 125
buy 50
sell 93
buy 59
sell 123
buy 94
sell 106
buy 93
sell 119
buy 71
sell 81
buy 98
sell 96
buy 63
sell 81
buy 72
sell 84
buy 75
sell 87
buy 63
sell 80
buy 59
sell 85
buy 81
sell 103
buy 90
sell 108
buy 57
sell 85
buy 85
sell 84
buy 92
sell 91
buy 59
sell 97
buy 57
sell 108
buy 98
sell 86
buy 59
sell 84
buy 86
sell 96
buy 93
sell 125
buy 99
sell 116
buy 91
sell 108
buy 96
sell 95
buy 88
sell 123
buy 63
sell 119
buy 55
sell 123
buy 70
sell 130
buy 94
sell 119
buy 59
sell 128
buy 52
sell 112
buy 69
sell 91
buy 79
sell 120
buy 59
sell 130
buy 79
sell 118
buy 67
sell 87
buy 98
sell 115
buy 62
sell 124
buy 76
sell 129
buy 76
sell 91
buy 72
sell 107
buy 72
sell 86
buy 84
sell 118
buy 93
sell 130
buy 54
sell 122
buy 73
sell 122
buy 79
sell 91
buy 97
sell 96
buy 62
sell 88
buy 62
sell 92
buy 93
sell 85
buy 95
sell 86
buy 72
sell 121
buy 73
sell 108
buy 59
sell 113
buy 98
sell 119
buy 64
sell 122
buy 82
sell 116
buy 66
sell 130
buy 78
sell 130
buy 77
sell 109
buy 96
sell 86
buy 100
sell 109
buy 64
sell 117
buy 76
sell 90
buy 74
sell 128
buy 86
sell 85
buy 52
sell 93
buy 77
sell 101
buy 73
sell 95
buy 50
sell 94
buy 70
sell 125
buy 87
sell 99
buy 80
sell 109
buy 66
sell 100
buy 76
sell 98
buy 69
sell 93
buy 87
sell 94
buy 78
sell 85
buy 54
sell 113
buy 97
sell 91
buy 75
sell 116
buy 83
sell 124
buy 69
sell 112
buy 54
sell 113
buy 97
sell 114
buy 95
sell 97
buy 65
sell 108
buy 94
sell 87
buy 78
sell 83
buy 64
sell 80
buy 87
sell 124
buy 56
sell 84
buy 63
sell 87
buy 93
sell 82
buy 79
sell 81
buy 96
sell 124
buy 69
sell 94
buy 54
sell 104
buy 56
sell 112
buy 96
sell 129
buy 51
sell 98
buy 62
sell 112
buy 70
sell 104
buy 51
sell 125
buy 63
sell 129
buy 78
sell 96
buy 63
sell 111
buy 96
sell 91
buy 93
sell 110
buy 80
sell 122
buy 74
sell 125
buy 74
sell 123
buy 72
sell 90
buy 87
sell 110
buy 81
sell 110
buy 50
sell 88
buy 69
sell 112
buy 64
sell 121
buy 99
sell 125
buy 78
sell 94
buy 71
sell 129
buy 74
sell 84
buy 95
sell 130
buy 66
sell 86
buy 72
sell 107
buy 59
sell 101
buy 73
sell 118
buy 92
sell 106
buy 82
sell 107
buy 58
